{
 "cells": [
  {
   "cell_type": "markdown",
   "metadata": {},
   "source": [
    "### **4.8 - [Práctica] Creating task dependencies between Dag Runs**"
   ]
  },
  {
   "cell_type": "markdown",
   "metadata": {},
   "source": [
    "<center><img src=\"https://i.postimg.cc/28XHff6P/a661.png\"></center>"
   ]
  },
  {
   "cell_type": "markdown",
   "metadata": {},
   "source": [
    "#### **`depends_on_past`**\n",
    "\n",
    "Agregamos a la tarea python_task_2 la dependencia depends_on_past=True\n",
    "\n",
    "<center><img src=\"https://i.postimg.cc/vm5X9gzs/a662.png\"></center>\n",
    "\n",
    "Entendiendo que el Schedule_interval está configurado para ejecutarse cada medianoche a partir del 01/01/2019:\n",
    "\n",
    "<center><img src=\"https://i.postimg.cc/3x4t8b0W/a663.png\"></center>\n",
    "\n",
    "El primer DAG Run efectivamente ejecutado ocurre el 02/01/2019 a las 00:00 :\n",
    "\n",
    "<center><img src=\"https://i.postimg.cc/GtmjZM1L/a664.png\"></center>\n",
    "\n",
    "Todas las tareas fueron ejecutadas correctamente:\n",
    "\n",
    "<center><img src=\"https://i.postimg.cc/BnrMXc2p/a665.png\"></center>\n",
    "\n",
    "Ahora, vamos a plantear una excepción de la función tercera tarea:\n",
    "\n",
    "<center><img src=\"https://i.postimg.cc/kGYy9xnx/a666.png\"></center>\n",
    "\n",
    "Como podíamos esperar, tenemos la tercera tarea en estado fallido (failed) como se muestra por el cuadrado rojo aquí, convirtiendo todo el DagRun en estado fallido (failed) como bien representa el círculo rojo aquí.\n",
    "\n",
    "<center><img src=\"https://i.postimg.cc/501gm47F/a667.png\"></center>\n",
    "\n",
    "Por cierto, puedes consultar los logs para saber qué ha pasado haciendo clic en la task instance, y luego en View log (ahora es “Logs”), y aquí tenemos la excepción que lanzamos desde el código.\n",
    "\n",
    "<center><img src=\"https://i.postimg.cc/bJTTC7WV/a668.png\"></center>\n",
    "<center><img src=\"https://i.postimg.cc/ryfjSLSK/a669.png\"></center>\n",
    "<center><img src=\"https://i.postimg.cc/JzkQVDSk/a670.png\"></center>\n",
    "\n",
    "Ahora hacemos lo siguiente en nuestro código y luego nuevamente ejecutamos nuestro DAG:\n",
    "\n",
    "<center><img src=\"https://i.postimg.cc/5t5qjc49/a671.png\"></center>\n",
    "\n",
    "Una vez hecho esto hay dos cosas que notar. La primera, second_task está en estado 'failed' lo cual es normal ya que hemos levantado una excepción de ella. La segunda cosa a notar es que la última tarea está en estado 'upstream_failed' como muestra el cuadrado naranja. Básicamente, significa que la tarea padre ha fallado y por lo tanto no se ha disparado.\n",
    "\n",
    "<center><img src=\"https://i.postimg.cc/gk5KTqtp/a672.png\"></center>\n",
    "\n",
    "Ahora volvemos a dejar las funciones como estaban en un principio y volvemos a ejecutar nuestro DAG:\n",
    "\n",
    "<center><img src=\"https://i.postimg.cc/MTd7byfh/a673.png\"></center>\n",
    "\n",
    "La ejecución de la tarea python_task_2 aquí depende de cómo haya terminado la misma tarea en el DagRun anterior. Como en el DagRun anterior la tarea ha fallado, no se activa en el DagRun actual. El parámetro depends_on_past evita que se ejecute la tarea ya que su ejecución anterior ha fallado.\n",
    "\n",
    "<center><img src=\"https://i.postimg.cc/1z1r9RZY/a674.png\"></center>\n",
    "\n",
    "___"
   ]
  },
  {
   "cell_type": "markdown",
   "metadata": {},
   "source": [
    "#### **`wait_for_downstream`**\n",
    "\n",
    "Agregamos a la tarea **`bash_task_1`** la dependencia **`wait_for_downstream=True`**\n",
    "\n",
    "<center><img src=\"https://i.postimg.cc/mkkQdtQh/a675.png\"></center>\n",
    "\n",
    "Entendiendo que el Schedule_interval está configurado para ejecutarse cada medianoche a partir del 01/01/2019:\n",
    "\n",
    "<center><img src=\"https://i.postimg.cc/0Q8GwtjY/a676.png\"></center>\n",
    "\n",
    "El primer DAG Run efectivamente ejecutado ocurre el 02/01/2019 a las 00:00 : \n",
    "\n",
    "<center><img src=\"https://i.postimg.cc/3Nq2zYB1/a677.png\"></center>\n",
    "\n",
    "En la Tree View vemos que las tareas se ejecutaron correctamente:\n",
    "\n",
    "<center><img src=\"https://i.postimg.cc/7Pt15nkz/a678.png\"></center>\n",
    "\n",
    "Ahora, vamos a plantear una excepción de la función second_task:\n",
    "\n",
    "<center><img src=\"https://i.postimg.cc/dtz8BQDt/a679.png\"></center>\n",
    "\n",
    "Como era de esperar, tenemos la segunda tarea con error y la tercera con el estado upstream_failed. Nada nuevo. \n",
    "\n",
    "<center><img src=\"https://i.postimg.cc/vH1rfxYN/a680.png\"></center>\n",
    "\n",
    "Ahora volvemos a dejar las funciones como estaban en un principio y volvemos a ejecutar nuestro DAG:\n",
    "\n",
    "<center><img src=\"https://i.postimg.cc/k41StqkC/a681.png\"></center>\n",
    "\n",
    "En el nuevo DAG Run ninguna de las tareas se activará. ¿Qué ha pasado aquí? Bueno, como la segunda tarea python_task_2 ha fallado en el DagRun anterior y porque está inmediatamente después de la tarea bash_task_1, esa misma tarea no se ha ejecutado en el DagRun actual. En realidad, ninguna de las tareas se ha ejecutado porque la primera tarea que se dispara en el DAG es bash _task_1. Si queremos que el DagRun se ejecute, sólo tenemos que cambiar el estado de la segunda tarea en el DagRun anterior de failed a success.\n",
    "\n",
    "<center><img src=\"https://i.postimg.cc/52L8kcF5/a682.png\"></center>\n",
    "\n",
    "**Como volver a ejecutar la tarea fallida usando “Clear”**\n",
    "\n",
    "En realidad, sólo para mostrar cómo se puede volver a ejecutar una tarea fallida, vamos a borrar (clear) su estado de la metadatabase. Para ello, haz clic en la tarea aquí y haz clic en \"Clear\". Como puede ver en el mensaje de arriba, 2 tareas han sido borradas, lo que significa que están listas para ser ejecutadas. Actualice la página varias veces y verás que tus DagRuns se están completando. Y ya está hecho. Porque la segunda tarea del DagRun anterior ha tenido éxito, entonces el DagRun actual ha podido activar la primera tarea con el parámetro wait_for_downstream.\n",
    "\n",
    "1.\tDamos clic en la tarea fallida:\n",
    "\n",
    "<center><img src=\"https://i.postimg.cc/43GVD8zD/a683.png\"></center>\n",
    "\n",
    "2.\tPulsamos CLEAR\n",
    "\n",
    "<center><img src=\"https://i.postimg.cc/k4X84BYw/a684.png\"></center>\n",
    "<center><img src=\"https://i.postimg.cc/HLtXdQzV/a685.png\"></center>\n",
    "\n",
    "Dado que habíamos modificado el código para que ninguna tarea devolviera un error, de esta manera con CLEAR nos permite borrar los resultados fallidos obtenidos y así volver a re ejecutar desde la tarea fallida en adelante.\n",
    "\n",
    "<center><img src=\"https://i.postimg.cc/QCvW0S8n/a686.png\"></center>\n",
    "<center><img src=\"https://i.postimg.cc/Gt4yF6Cy/a687.png\"></center>"
   ]
  }
 ],
 "metadata": {
  "language_info": {
   "name": "python"
  }
 },
 "nbformat": 4,
 "nbformat_minor": 2
}
